Is all the socket in ping.raw and the dataxferservice being closed properly even after
exception is being thrown?